<?xml version="1.0"?>

  <robot name="robot" xmlns:xacro="http://www.ros.org/wiki/xacro">
   
   
   
   
      <!-- BODY DRIVE WHEEL URDF -->
   <link name="base_link">

       <visual>
   	        <origin rpy="0 0 0" xyz="0 0. 0"/>
          <geometry>
              <box size="0.7 0.7 1.2"/>
         </geometry>
         <material name="grey">
          <color rgba="0.6 0.6 0.6 1"/>
        </material>
       </visual>

       <collision>
        <origin rpy="0 0 0" xyz="0 0. 0"/>
        <geometry>
            <box size="0.7 0.7 1.2"/>
       </geometry>
       </collision>

       <inertial>
        <origin xyz="0 0 0" rpy="0 0 0"/>
        <mass value="3"/>
        <inertia
          ixx="1.0" ixy="1" ixz="1"
          iyy="1.0" iyz="1"
          izz="1.0"/>
      </inertial>

    </link>
    <!-- RIGHT DRIVE WHEEL URDF -->
   <joint name="body_right_wheel" type="continuous">
   	<axis xyz="0 0 -1"/>
    	<parent link="base_link"/>
      <child link="right_wheel"/>
      <origin rpy="1.5707 0 0" xyz="0 -0.41 -0.600"/>
      <limit effort="30" velocity="1.0" lower="-2.2" upper="0.7" />
      
   </joint>
   
   <link name="right_wheel">

       <visual>
   	<origin rpy="0 0 0" xyz="0 0 0"/>
        <geometry>
          <cylinder length="0.1" radius="0.1"/>
        </geometry>
        <material name="Light_grey">
          <color rgba="0.8 0.8 0.8 1"/>
        </material>
      </visual>

      <collision>
        <origin rpy="0 0 0" xyz="0 0 0"/>
        <geometry>
          <cylinder length="0.1" radius="0.1"/>
        </geometry>
      </collision>

      <inertial>
        <origin xyz="0 0 0" rpy="0 0 0"/>
        <mass value="1"/>
        <inertia ixx="0.005" ixy="0.0" ixz="0.0" iyy="0.005" iyz="0.0" izz="0.005"/>
      </inertial>
  </link>

   <!-- LEFT DRIVE WHEEL URDF -->
    <joint name="body_left_wheel" type="continuous">
    	<axis xyz="0 0 -1"/>
     	<parent link="base_link"/>
      <child link="left_wheel"/>
      <origin rpy="1.5707 0 0" xyz="0 0.41 -0.600"/>
      <limit effort="30" velocity="1.0" lower="-2.2" upper="0.7" />
       </joint>
   
   <link name="left_wheel">

       <visual>
        <origin rpy="0 0 0" xyz="0 0 0"/>
         <geometry>
           <cylinder length="0.1" radius="0.1"/>
        </geometry>
        <material name="Light_grey">
          <color rgba="0.8 0.8 0.8 1"/>
        </material>
      </visual>

      <collision>
        <origin rpy="0 0 0" xyz="0 0 0"/>
         <geometry>
           <cylinder length="0.1" radius="0.1"/>
        </geometry>
      </collision>

      <inertial>
        <origin xyz="0 0 0" rpy="0 0 0"/>
        <mass value="1"/>
        <inertia ixx="0.005" ixy="0.0" ixz="0.0" iyy="0.005" iyz="0.0" izz="0.005"/>
      </inertial>
    </link>

    <!-- RIGHT PASSIVE WHEELS URDF -->
    <joint name="body_top_right_wheel" type="continuous">
   	<axis xyz="0 0 1"/>
    	<parent link="base_link"/>
      <child link="top_right_wheel_passive"/>
      <origin rpy="1.5707 0 0" xyz="0.35 -0.41 -0.600"/>
      <limit effort="30" velocity="1.0" lower="-2.2" upper="0.7" />
      
   </joint>
   
   <link name="top_right_wheel_passive">

       <visual>
        <origin rpy="0 0 0" xyz="0 0 0"/>
        <geometry>
          <cylinder length="0.1" radius="0.1"/>
        </geometry>
        <material name="Light_grey">
          <color rgba="0.8 0.8 0.8 1"/>
        </material>
      </visual>

      <collision>
        <origin rpy="0 0 0" xyz="0 0 0"/>
        <geometry>
          <cylinder length="0.1" radius="0.1"/>
        </geometry>
      </collision>

      <inertial>
        <origin xyz="0 0 0" rpy="0 0 0"/>
        <mass value="1"/>
        <inertia ixx="0.005" ixy="0.0" ixz="0.0" iyy="0.005" iyz="0.0" izz="0.005"/>
      </inertial>

  </link>

  <joint name="body_bottom_right_wheel" type="continuous">
    <axis xyz="0 0 1"/>
     <parent link="base_link"/>
     <child link="bottom_right_wheel_passive"/>
     <origin rpy="1.5707 0 0" xyz="-0.35 -0.41 -0.600"/>
     <limit effort="30" velocity="1.0" lower="-2.2" upper="0.7" />
     
  </joint>
  
  <link name="bottom_right_wheel_passive">

      <visual>
        <origin rpy="0 0 0" xyz="0 0 0"/>
       <geometry>
         <cylinder length="0.1" radius="0.1"/>
       </geometry>
       <material name="Light_grey">
         <color rgba="0.8 0.8 0.8 1"/>
       </material>
     </visual>

     <collision>
      <origin rpy="0 0 0" xyz="0 0 0"/>
       <geometry>
         <cylinder length="0.1" radius="0.1"/>
       </geometry>
     </collision>

     <inertial>
      <origin xyz="0 0 0" rpy="0 0 0"/>
      <mass value="1"/>
      <inertia ixx="0.005" ixy="0.0" ixz="0.0" iyy="0.005" iyz="0.0" izz="0.005"/>
    </inertial>

 </link>

    <!-- LEFT PASSIVE WHEELS URDF -->
    <joint name="body_top_left_wheel" type="continuous">

      <axis xyz="0 0 1"/>
       <parent link="base_link"/>
       <child link="top_left_wheel_passive"/>
       <origin rpy="1.5707 0 0" xyz="0.35 0.41 -0.600"/>
       <limit effort="30" velocity="1.0" />
       
    </joint>
    
    <link name="top_left_wheel_passive">

        <visual>
          <origin rpy="0 0 0" xyz="0 0 0"/>
         <geometry>
           <cylinder length="0.1" radius="0.1"/>
         </geometry>
         <material name="Light_grey">
           <color rgba="0.8 0.8 0.8 1"/>
         </material>
       </visual>

       <collision>
        <origin rpy="0 0 0" xyz="0 0 0"/>
         <geometry>
           <cylinder length="0.1" radius="0.1"/>
         </geometry>
       </collision>

       <inertial>
        <origin xyz="0 0 0" rpy="0 0 0"/>
        <mass value="1"/>
        <inertia ixx="0.005" ixy="0.0" ixz="0.0" iyy="0.005" iyz="0.0" izz="0.005"/> 
      </inertial>

   </link>
 
   <joint name="body_bottom_left_wheel" type="continuous">

     <axis xyz="0 0 1"/>
      <parent link="base_link"/>
      <child link="bottom_left_wheel_passive"/>
      <origin rpy="1.5707 0 0" xyz="-0.35 0.41 -0.600"/>
      <limit effort="30" velocity="1.0" />
      
   </joint>
   
   <link name="bottom_left_wheel_passive">

       <visual>
        <origin rpy="0 0 0" xyz="0 0 0"/>
        <geometry>
          <cylinder length="0.1" radius="0.1"/>
        </geometry>
        <material name="Light_grey">
          <color rgba="0.8 0.8 0.8 1"/>
        </material>
      </visual>

      <collision>
        <origin rpy="0 0 0" xyz="0 0 0"/>
        <geometry>
          <cylinder length="0.1" radius="0.1"/>
        </geometry> 
      </collision>

      <inertial>
        <origin xyz="0 0 0" rpy="0 0 0"/>
        <mass value="1"/>
        <inertia ixx="0.005" ixy="0.0" ixz="0.0" iyy="0.005" iyz="0.0" izz="0.005"/>
      </inertial>

  </link>

<!-- pointcould camera link an joint -->

  <joint name="camera_to_body" type="fixed">

      <parent link="base_link"/>
      <child link="camera_link"/>
      <origin rpy="0 1.22173 0" xyz="0.35 0 0.650"/>

   </joint>


  <link name="camera_link">

  </link>













   
   <!--The gazebo settings are going to be here -->



   <!-- THE DIFFERETIAL DRIVE SETTINGS-->
   <gazebo>
    <plugin name="differential_drive_controller" filename="libgazebo_ros_diff_drive.so">
  
      <!-- Plugin update rate in Hz -->
      <updateRate>20</updateRate>
  
      <!-- Name of left joint, defaults to `left_joint` -->
      <leftJoint>body_left_wheel</leftJoint>
  
      <!-- Name of right joint, defaults to `right_joint` -->
      <rightJoint>body_right_wheel</rightJoint>
  
      <!-- The distance from the center of one wheel to the other, in meters, defaults to 0.34 m -->
      <wheelSeparation>0.73</wheelSeparation>
  
      <!-- Diameter of the wheels, in meters, defaults to 0.15 m -->
      <wheelDiameter>0.2</wheelDiameter>
  
      <!-- Wheel acceleration, in rad/s^2, defaults to 0.0 rad/s^2 -->
      <wheelAcceleration>1.0</wheelAcceleration>
  
      <!-- Maximum torque which the wheels can produce, in Nm, defaults to 5 Nm -->
      <wheelTorque>1000</wheelTorque>
  
      <!-- Topic to receive geometry_msgs/Twist message commands, defaults to `cmd_vel` -->
      <commandTopic>cmd_vel</commandTopic>
  
      <!-- Topic to publish nav_msgs/Odometry messages, defaults to `odom` -->
      <odometryTopic>odom</odometryTopic>
  
      <!-- Odometry frame, defaults to `odom` -->
      <odometryFrame>odom</odometryFrame>
  
      <!-- Robot frame to calculate odometry from, defaults to `base_footprint` -->
      <robotBaseFrame>base_link</robotBaseFrame>
  
      <!-- Odometry source, 0 for ENCODER, 1 for WORLD, defaults to WORLD -->
      <odometrySource>1</odometrySource>
  
      <!-- Set to true to publish transforms for the wheel links, defaults to false -->
      <publishWheelTF>true</publishWheelTF>
  
      <!-- Set to true to publish transforms for the odometry, defaults to true -->
      <publishOdom>true</publishOdom>
  
      <!-- Set to true to publish sensor_msgs/JointState on /joint_states for the wheel joints, defaults to false -->
      <publishWheelJointState>true</publishWheelJointState>
  
      <!-- Set to true to swap right and left wheels, defaults to true -->
      <legacyMode>true</legacyMode>
    </plugin>


  </gazebo>
   

  <!--Friction settings-->
  <gazebo reference="left_wheel">
    <mu1>0.9</mu1>
    <mu2>0.9</mu2>
    <material>Gazebo/Wood</material>
  </gazebo> 
  
  
  <gazebo reference="right_wheel">
    <mu1>0.9</mu1>
    <mu2>0.9</mu2>
    <material>Gazebo/Wood</material>
  </gazebo>   
  
  
  <gazebo reference="bottom_left_wheel_passive">
    <mu1>0.2</mu1>
    <mu2>0.2</mu2>
    <material>Gazebo/Black</material>
  </gazebo>   
   

  <gazebo reference="bottom_right_wheel_passive">
    <mu1>0.2</mu1>
    <mu2>0.2</mu2>
    <material>Gazebo/Black</material>
  </gazebo>  
  
    
  <gazebo reference="top_left_wheel_passive">
    <mu1>0.2</mu1>
    <mu2>0.2</mu2>
    <material>Gazebo/Black</material>
  </gazebo>   
   

  <gazebo reference="top_right_wheel_passive">
    <mu1>0.2</mu1>
    <mu2>0.2</mu2>
    <material>Gazebo/Black</material>
  </gazebo>   
  

  <!-- LIDAR SETTINGS -->

  <gazebo reference="base_link">
    <sensor type="ray" name="head_hokuyo_sensor">
      <pose>0 0 0.7 0 0 0</pose>
      <visualize>true</visualize>
      <update_rate>40</update_rate>
      <ray>
        <scan>
          <horizontal>
            <samples>720</samples>
            <resolution>1</resolution>
            <min_angle>-3.141592653</min_angle>
            <max_angle>3.141592653</max_angle>
          </horizontal>
        </scan>
        <range>
          <min>0.10</min>
          <max>30.0</max>
          <resolution>0.01</resolution>
        </range>
        <noise>
          <type>gaussian</type>
          <!-- Noise parameters based on published spec for Hokuyo laser
               achieving "+-30mm" accuracy at range < 10m.  A mean of 0.0m and
               stddev of 0.01m will put 99.7% of samples within 0.03m of the true
               reading. -->
          <mean>0.0</mean>
          <stddev>0.01</stddev>
        </noise>
      </ray>
      <plugin name="gazebo_ros_head_hokuyo_controller" filename="libgazebo_ros_laser.so">
        <topicName>/rrbot/laser/scan</topicName>
        <frameName>base_link</frameName>
      </plugin>
    </sensor>
  </gazebo>
   
  <!-- pountcloud camera plugin setting and startup-->

  <gazebo reference="camera_link">
    <sensor name="camera_link_camera" type="depth">
      <update_rate>20</update_rate>
      <camera>
        <horizontal_fov>1.047198</horizontal_fov>
        <image>
          <width>640</width>
          <height>480</height>
          <format>R8G8B8</format>
        </image>
        <clip>
          <near>0.05</near>
          <far>20</far>
        </clip>
      </camera>
      <plugin name="camera_link_controller" filename="libgazebo_ros_openni_kinect.so">
        <baseline>0.2</baseline>
        <alwaysOn>true</alwaysOn>
        <updateRate>1.0</updateRate>
        <cameraName>kinect_ros</cameraName>
        <imageTopicName>/camera_name/color/image_raw</imageTopicName>
        <cameraInfoTopicName>/kinect_ros/color/camera_info</cameraInfoTopicName>
        <depthImageTopicName>/kinect_ros/depth/image_raw</depthImageTopicName>
        <depthImageInfoTopicName>/kinect_ros/depth/camera_info</depthImageInfoTopicName>
        <pointCloudTopicName>/kinect_ros/depth/points</pointCloudTopicName>
        <frameName>base_link</frameName>
        <pointCloudCutoff>0.5</pointCloudCutoff>
        <pointCloudCutoffMax>3.0</pointCloudCutoffMax>
        <distortionK1>0.00000001</distortionK1>
        <distortionK2>0.00000001</distortionK2>
        <distortionK3>0.00000001</distortionK3>
        <distortionT1>0.00000001</distortionT1>
        <distortionT2>0.00000001</distortionT2>
        <CxPrime>0</CxPrime>
        <Cx>0</Cx>
        <Cy>0</Cy>
        <focalLength>0</focalLength>
        <hackBaseline>0</hackBaseline>
      </plugin>
    </sensor>
  </gazebo>










   </robot>
  
