<?xml version="1.0"?>

   2 <robot name="robot">
   
   3   <link name="body">
   4     <visual>
   	<origin rpy="0 0 0" xyz="0 0. 0"/>
   5       <geometry>
   6         <box size="0.7 0.7 1.2"/>
   7       </geometry>
   8     </visual>
   	<collision>
   	<geometry>
   6         <box size="0.7 0.7 1.2"/>
   7       </geometry>
   	</collision>
   9   </link>
   
   <joint name="body_right_wheel" type="revolute">
   	<axis xyz="0 0 1"/>
    	<parent link="base"/>
  65     <child link="right_wheel"/>
  66     <origin rpy="0 0 0" xyz="0 0 0"/>
   </joint>
   
   <link name="right_wheel">
   4     <visual>
   	<origin rpy="-3.1415 0 0" xyz="0.09137 0.00495 0"/>
   5       <geometry>
   6         <cylinder length="0.1" radius="0.5"/>
   7       </geometry>
   8     </visual>
   	<collision>
   	<geometry>
   6         <cylinder length="0.1" radius="0.5"/>
   7       </geometry>
   	</collision>
   9   </link>
   
    <joint name="body_right_wheel" type="revolute">
    	<axis xyz="0 0 1"/>
     	<parent link="base"/>
  65     <child link="left_wheel"/>
  66     <origin rpy="0 0 0" xyz="0.133333333333 0 -0.085"/>
       </joint>
   
   <link name="left_wheel">
   4     <visual>
   	<origin rpy="-3.1415 0 0" xyz="0.09137 0.00495 0"/>
   5       <geometry>
   6         <cylinder length="0.1" radius="0.5"/>
   7       </geometry>
   8     </visual>
   	<collision>
   	<geometry>
   6         <cylinder length="0.1" radius="0.5"/>
   7       </geometry>
   	</collision>
   9   </link>
   
   
   
   
   
   
   
   
  10 </robot>
  
